<?xml version="1.0" encoding="utf-8"?>
<!-- This URDF was automatically created by SolidWorks to URDF Exporter! Originally created by Stephen Brawner (brawner@gmail.com) 
     Commit Version: 1.6.0-1-g15f4949  Build Version: 1.6.7594.29634
     For more information, please see http://wiki.ros.org/sw_urdf_exporter -->
<robot
  name="twoleg_foot_link">
  <link
    name="base_link">
    <inertial>
      <origin
        xyz="-0.013643004895774 7.93162980589689E-07 0.0859988058711454"
        rpy="0 0 0" />
      <mass
        value="3.10945390199589" />
      <inertia
        ixx="0.00934001308296876"
        ixy="-1.9041605187863E-09"
        ixz="1.49895631162145E-07"
        iyy="0.0217925945259764"
        iyz="-3.80295188181027E-08"
        izz="0.0240800105411559" />
    </inertial>
    <visual>
      <origin
        xyz="0 0 0"
        rpy="0 0 0" />
      <geometry>
        <mesh
          filename="package://twoleg_foot_link/meshes/base_link.STL" />
      </geometry>
      <material
        name="">
        <color
          rgba="0 0 0 1" />
      </material>
    </visual>
    <collision>
      <origin
        xyz="0 0 0"
        rpy="0 0 0" />
      <geometry>
        <mesh
          filename="package://twoleg_foot_link/meshes/base_link.STL" />
      </geometry>
    </collision>
  </link>
  <link
    name="Left_Link1">
    <inertial>
      <origin
        xyz="0.0079825523298408 -4.50865902585394E-05 0.0367881420274613"
        rpy="0 0 0" />
      <mass
        value="0.238485739146011" />
      <inertia
        ixx="0.00016047963206388"
        ixy="-1.70377510394896E-08"
        ixz="2.36990442421365E-06"
        iyy="0.000162839075296289"
        iyz="8.40873201521934E-08"
        izz="0.000140875618411013" />
    </inertial>
    <visual>
      <origin
        xyz="0 0 0"
        rpy="0 0 0" />
      <geometry>
        <mesh
          filename="package://twoleg_foot_link/meshes/Left_Link1.STL" />
      </geometry>
      <material
        name="">
        <color
          rgba="0.854901960784314 0.854901960784314 0.854901960784314 1" />
      </material>
    </visual>
    <collision>
      <origin
        xyz="0 0 0"
        rpy="0 0 0" />
      <geometry>
        <mesh
          filename="package://twoleg_foot_link/meshes/Left_Link1.STL" />
      </geometry>
    </collision>
  </link>
  <joint
    name="Left_Joint1"
    type="revolute">
    <origin
      xyz="0.126001345954292 0 0.0577144013466578"
      rpy="3.14159265358979 -0.785398163397443 0" />
    <parent
      link="base_link" />
    <child
      link="Left_Link1" />
    <axis
      xyz="0 0 -1" />
    <limit
      lower="-2.093"
      upper="2.093"
      effort="9"
      velocity="4" />
  </joint>
  <link
    name="Left_Link2">
    <inertial>
      <origin
        xyz="-2.59212361961045E-05 -0.0478095316134823 -0.0104737983474142"
        rpy="0 0 0" />
      <mass
        value="0.124068775292257" />
      <inertia
        ixx="8.2152871682514E-05"
        ixy="-6.24494359433284E-09"
        ixz="-3.57216894518165E-08"
        iyy="3.44293185125146E-05"
        iyz="2.83186405787448E-06"
        izz="9.22034985201146E-05" />
    </inertial>
    <visual>
      <origin
        xyz="0 0 0"
        rpy="0 0 0" />
      <geometry>
        <mesh
          filename="package://twoleg_foot_link/meshes/Left_Link2.STL" />
      </geometry>
      <material
        name="">
        <color
          rgba="1 1 1 1" />
      </material>
    </visual>
    <collision>
      <origin
        xyz="0 0 0"
        rpy="0 0 0" />
      <geometry>
        <mesh
          filename="package://twoleg_foot_link/meshes/Left_Link2.STL" />
      </geometry>
    </collision>
  </link>
  <joint
    name="Left_Joint2"
    type="revolute">
    <origin
      xyz="0.04275 0 0.0410500000000001"
      rpy="-1.5707963267949 0 1.5707963267949" />
    <parent
      link="Left_Link1" />
    <child
      link="Left_Link2" />
    <axis
      xyz="0 0 -1" />
    <limit
      lower="-2.093"
      upper="2.093"
      effort="9"
      velocity="4" />
  </joint>
  <link
    name="Left_Link3">
    <inertial>
      <origin
        xyz="1.115432175216E-05 -0.0160034117315548 -0.0377275570862976"
        rpy="0 0 0" />
      <mass
        value="0.154593855527533" />
      <inertia
        ixx="7.48360086999987E-05"
        ixy="8.92895374741489E-09"
        ixz="2.87062145894065E-08"
        iyy="8.38191871420754E-05"
        iyz="-8.95868503158221E-06"
        izz="6.20708624383725E-05" />
    </inertial>
    <visual>
      <origin
        xyz="0 0 0"
        rpy="0 0 0" />
      <geometry>
        <mesh
          filename="package://twoleg_foot_link/meshes/Left_Link3.STL" />
      </geometry>
      <material
        name="">
        <color
          rgba="1 1 1 1" />
      </material>
    </visual>
    <collision>
      <origin
        xyz="0 0 0"
        rpy="0 0 0" />
      <geometry>
        <mesh
          filename="package://twoleg_foot_link/meshes/Left_Link3.STL" />
      </geometry>
    </collision>
  </link>
  <joint
    name="Left_Joint3"
    type="revolute">
    <origin
      xyz="0 -0.0969 -0.0110500000000001"
      rpy="-1.5707963267949 0 0" />
    <parent
      link="Left_Link2" />
    <child
      link="Left_Link3" />
    <axis
      xyz="0 0 -1" />
    <limit
      lower="-3.14"
      upper="3.14"
      effort="1"
      velocity="15" />
  </joint>
  <link
    name="Left_Link4">
    <inertial>
      <origin
        xyz="5.79600776105718E-05 -0.0716988597958203 0.00570636373232708"
        rpy="0 0 0" />
      <mass
        value="0.145990900684867" />
      <inertia
        ixx="0.000190396621110576"
        ixy="7.81613638782874E-07"
        ixz="9.31454388057964E-08"
        iyy="3.62993395743349E-05"
        iyz="-1.86542623690101E-05"
        izz="0.000193175937759761" />
    </inertial>
    <visual>
      <origin
        xyz="0 0 0"
        rpy="0 0 0" />
      <geometry>
        <mesh
          filename="package://twoleg_foot_link/meshes/Left_Link4.STL" />
      </geometry>
      <material
        name="">
        <color
          rgba="1 1 1 1" />
      </material>
    </visual>
    <collision>
      <origin
        xyz="0 0 0"
        rpy="0 0 0" />
      <geometry>
        <mesh
          filename="package://twoleg_foot_link/meshes/Left_Link4.STL" />
      </geometry>
    </collision>
  </link>
  <joint
    name="Left_Joint4"
    type="revolute">
    <origin
      xyz="0 0.00799999999999998 -0.0409999999999999"
      rpy="1.5707963267949 0 -3.14159265358979" />
    <parent
      link="Left_Link3" />
    <child
      link="Left_Link4" />
    <axis
      xyz="0 0 -1" />
    <limit
      lower="-2.093"
      upper="2.093"
      effort="3"
      velocity="12" />
  </joint>
  <link
    name="Left_Link5">
    <inertial>
      <origin
        xyz="-5.31128774811907E-05 0.00235248627116813 0.0301999304388426"
        rpy="0 0 0" />
      <mass
        value="0.0964184787571057" />
      <inertia
        ixx="3.34601332651236E-05"
        ixy="7.71338632741261E-09"
        ixz="-1.99376169154418E-08"
        iyy="3.88654105004541E-05"
        iyz="-3.79290943057307E-06"
        izz="2.75749493418456E-05" />
    </inertial>
    <visual>
      <origin
        xyz="0 0 0"
        rpy="0 0 0" />
      <geometry>
        <mesh
          filename="package://twoleg_foot_link/meshes/Left_Link5.STL" />
      </geometry>
      <material
        name="">
        <color
          rgba="1 1 1 1" />
      </material>
    </visual>
    <collision>
      <origin
        xyz="0 0 0"
        rpy="0 0 0" />
      <geometry>
        <mesh
          filename="package://twoleg_foot_link/meshes/Left_Link5.STL" />
      </geometry>
    </collision>
  </link>
  <joint
    name="Left_Joint5"
    type="revolute">
    <origin
      xyz="0 -0.1364 0.001"
      rpy="1.5708 0 0" />
    <parent
      link="Left_Link4" />
    <child
      link="Left_Link5" />
    <axis
      xyz="0 0 -1" />
    <limit
      lower="-3.14"
      upper="3.14"
      effort="1"
      velocity="15" />
  </joint>
  <link
    name="Left_Link6">
    <inertial>
      <origin
        xyz="8.03632821800492E-19 -5.55111512312578E-17 0.00600000000000012"
        rpy="0 0 0" />
      <mass
        value="0.00706858347057702" />
      <inertia
        ixx="4.56512682474766E-07"
        ixy="4.47185316823312E-24"
        ixz="5.32502121779042E-23"
        iyy="4.56512682474766E-07"
        iyz="-6.6174449004241E-23"
        izz="7.95215640439915E-07" />
    </inertial>
    <visual>
      <origin
        xyz="0 0 0"
        rpy="0 0 0" />
      <geometry>
        <mesh
          filename="package://twoleg_foot_link/meshes/Left_Link6.STL" />
      </geometry>
      <material
        name="">
        <color
          rgba="1 1 1 1" />
      </material>
    </visual>
    <collision>
      <origin
        xyz="0 0 0"
        rpy="0 0 0" />
      <geometry>
        <mesh
          filename="package://twoleg_foot_link/meshes/Left_Link6.STL" />
      </geometry>
    </collision>
  </link>
  <joint
    name="Left_Joint6"
    type="revolute">
    <origin
      xyz="0 -0.0174 0.036"
      rpy="-1.5708 0 3.1416" />
    <parent
      link="Left_Link5" />
    <child
      link="Left_Link6" />
    <axis
      xyz="0 0 -1" />
    <limit
      lower="-3.14"
      upper="3.14"
      effort="1"
      velocity="15" />
  </joint>
  <link
    name="Left_Foot">
    <inertial>
      <origin
        xyz="2.22044604925031E-16 3.81827202897513E-17 0.0195816701322208"
        rpy="0 0 0" />
      <mass
        value="0.0394934474548919" />
      <inertia
        ixx="7.20293359743238E-06"
        ixy="-1.99514292633184E-22"
        ixz="-8.47032947254282E-22"
        iyy="7.20293359743238E-06"
        iyz="2.5976478581316E-22"
        izz="7.80281784174379E-06" />
    </inertial>
    <visual>
      <origin
        xyz="0 0 0"
        rpy="0 0 0" />
      <geometry>
        <mesh
          filename="package://twoleg_foot_link/meshes/Left_Foot.STL" />
      </geometry>
      <material
        name="">
        <color
          rgba="1 1 1 1" />
      </material>
    </visual>
    <collision>
      <origin
        xyz="0 0 0"
        rpy="0 0 0" />
      <geometry>
        <mesh
          filename="package://twoleg_foot_link/meshes/Left_Foot.STL" />
      </geometry>
    </collision>
  </link>
  <joint
    name="Left_Foot_Joint"
    type="fixed">
    <origin
      xyz="0 0 0.011"
      rpy="0 0 -1.5708" />
    <parent
      link="Left_Link6" />
    <child
      link="Left_Foot" />
    <axis
      xyz="0 0 0" />
  </joint>
  <link
    name="Right_Link1">
    <inertial>
      <origin
        xyz="-0.00798255232481621 -3.17460933430338E-05 0.0367341196326673"
        rpy="0 0 0" />
      <mass
        value="0.238485739194803" />
      <inertia
        ixx="0.00016047963210501"
        ixy="9.86789665342907E-09"
        ixz="-2.3509981898915E-06"
        iyy="0.000162935769054922"
        iyz="-1.00610547185295E-07"
        izz="0.000140778924712756" />
    </inertial>
    <visual>
      <origin
        xyz="0 0 0"
        rpy="0 0 0" />
      <geometry>
        <mesh
          filename="package://twoleg_foot_link/meshes/Right_Link1.STL" />
      </geometry>
      <material
        name="">
        <color
          rgba="1 1 1 1" />
      </material>
    </visual>
    <collision>
      <origin
        xyz="0 0 0"
        rpy="0 0 0" />
      <geometry>
        <mesh
          filename="package://twoleg_foot_link/meshes/Right_Link1.STL" />
      </geometry>
    </collision>
  </link>
  <joint
    name="Right_Joint1"
    type="revolute">
    <origin
      xyz="-0.153287975927055 0 0.0577144013466578"
      rpy="3.14159265358979 0.785398163397443 0" />
    <parent
      link="base_link" />
    <child
      link="Right_Link1" />
    <axis
      xyz="0 0 -1" />
    <limit
      lower="-2.093"
      upper="2.093"
      effort="9"
      velocity="4" />
  </joint>
  <link
    name="Right_Link2">
    <inertial>
      <origin
        xyz="-0.0478095323053693 -2.11778235935096E-07 0.0108020452989008"
        rpy="0 0 0" />
      <mass
        value="0.124068777086544" />
      <inertia
        ixx="3.44293184238918E-05"
        ixy="-1.10599914290492E-08"
        ixz="-2.84637782291539E-06"
        iyy="8.21279974534663E-05"
        iyz="2.72559241935656E-09"
        izz="9.22283725821581E-05" />
    </inertial>
    <visual>
      <origin
        xyz="0 0 0"
        rpy="0 0 0" />
      <geometry>
        <mesh
          filename="package://twoleg_foot_link/meshes/Right_Link2.STL" />
      </geometry>
      <material
        name="">
        <color
          rgba="1 1 1 1" />
      </material>
    </visual>
    <collision>
      <origin
        xyz="0 0 0"
        rpy="0 0 0" />
      <geometry>
        <mesh
          filename="package://twoleg_foot_link/meshes/Right_Link2.STL" />
      </geometry>
    </collision>
  </link>
  <joint
    name="Right_Joint2"
    type="revolute">
    <origin
      xyz="-0.0425 0 0.0410499999999999"
      rpy="3.14159265358979 1.5707963267949 0" />
    <parent
      link="Right_Link1" />
    <child
      link="Right_Link2" />
    <axis
      xyz="0 0 -1" />
    <limit
      lower="-2.093"
      upper="2.093"
      effort="9"
      velocity="4" />
  </joint>
  <link
    name="Right_Link3">
    <inertial>
      <origin
        xyz="-2.54038085041023E-05 -0.0160034117009831 0.037732752118776"
        rpy="0 0 0" />
      <mass
        value="0.15459385579605" />
      <inertia
        ixx="7.48514328485236E-05"
        ixy="-2.00191562540139E-08"
        ixz="2.28142277765459E-08"
        iyy="8.38191869508431E-05"
        iyz="8.96313524667185E-06"
        izz="6.2055438097884E-05" />
    </inertial>
    <visual>
      <origin
        xyz="0 0 0"
        rpy="0 0 0" />
      <geometry>
        <mesh
          filename="package://twoleg_foot_link/meshes/Right_Link3.STL" />
      </geometry>
      <material
        name="">
        <color
          rgba="1 1 1 1" />
      </material>
    </visual>
    <collision>
      <origin
        xyz="0 0 0"
        rpy="0 0 0" />
      <geometry>
        <mesh
          filename="package://twoleg_foot_link/meshes/Right_Link3.STL" />
      </geometry>
    </collision>
  </link>
  <joint
    name="Right_Joint3"
    type="revolute">
    <origin
      xyz="-0.0968999999999999 0 0.0113"
      rpy="1.5707963267949 0 -1.5707963267949" />
    <parent
      link="Right_Link2" />
    <child
      link="Right_Link3" />
    <axis
      xyz="0 0 -1" />
    <limit
      lower="-3.14"
      upper="3.14"
      effort="1"
      velocity="15" />
  </joint>
  <link
    name="Right_Link4">
    <inertial>
      <origin
        xyz="-8.40729039699683E-05 -0.0716988600198229 -0.00566598542958516"
        rpy="0 0 0" />
      <mass
        value="0.145990900982084" />
      <inertia
        ixx="0.000190327954853196"
        ixy="-7.75883477899461E-07"
        ixz="1.23123324923912E-07"
        iyy="3.62993395258124E-05"
        iyz="1.86454574363625E-05"
        izz="0.000193244603901421" />
    </inertial>
    <visual>
      <origin
        xyz="0 0 0"
        rpy="0 0 0" />
      <geometry>
        <mesh
          filename="package://twoleg_foot_link/meshes/Right_Link4.STL" />
      </geometry>
      <material
        name="">
        <color
          rgba="1 1 1 1" />
      </material>
    </visual>
    <collision>
      <origin
        xyz="0 0 0"
        rpy="0 0 0" />
      <geometry>
        <mesh
          filename="package://twoleg_foot_link/meshes/Right_Link4.STL" />
      </geometry>
    </collision>
  </link>
  <joint
    name="Right_Joint4"
    type="revolute">
    <origin
      xyz="0 0.00799999999999992 0.0410000000000001"
      rpy="-1.5707963267949 0 -3.14159265358979" />
    <parent
      link="Right_Link3" />
    <child
      link="Right_Link4" />
    <axis
      xyz="0 0 -1" />
    <limit
      lower="-2.093"
      upper="2.093"
      effort="3"
      velocity="12" />
  </joint>
  <link
    name="Right_Link5">
    <inertial>
      <origin
        xyz="-0.00235248632476492 -4.92778705946399E-05 0.0301594123899624"
        rpy="0 0 0" />
      <mass
        value="0.0964184778849923" />
      <inertia
        ixx="3.88654105033287E-05"
        ixy="-7.14323298892607E-09"
        ixz="3.78706490739583E-06"
        iyy="3.34498645747308E-05"
        iyz="3.07755838106135E-08"
        izz="2.75852180331046E-05" />
    </inertial>
    <visual>
      <origin
        xyz="0 0 0"
        rpy="0 0 0" />
      <geometry>
        <mesh
          filename="package://twoleg_foot_link/meshes/Right_Link5.STL" />
      </geometry>
      <material
        name="">
        <color
          rgba="1 1 1 1" />
      </material>
    </visual>
    <collision>
      <origin
        xyz="0 0 0"
        rpy="0 0 0" />
      <geometry>
        <mesh
          filename="package://twoleg_foot_link/meshes/Right_Link5.STL" />
      </geometry>
    </collision>
  </link>
  <joint
    name="Right_Joint5"
    type="revolute">
    <origin
      xyz="0 -0.1364 -0.001"
      rpy="1.5708 -1.5708 0" />
    <parent
      link="Right_Link4" />
    <child
      link="Right_Link5" />
    <axis
      xyz="0 0 -1" />
    <limit
      lower="-3.14"
      upper="3.14"
      effort="1"
      velocity="15" />
  </joint>
  <link
    name="Right_Link6">
    <inertial>
      <origin
        xyz="-5.55111512312578E-17 2.15995422848884E-19 -0.00599999999999995"
        rpy="0 0 0" />
      <mass
        value="0.00706858347057702" />
      <inertia
        ixx="4.56512682474766E-07"
        ixy="1.24959159105023E-24"
        ixz="2.64697796016971E-23"
        iyy="4.56512682474766E-07"
        iyz="-1.66783678182471E-23"
        izz="7.95215640439915E-07" />
    </inertial>
    <visual>
      <origin
        xyz="0 0 0"
        rpy="0 0 0" />
      <geometry>
        <mesh
          filename="package://twoleg_foot_link/meshes/Right_Link6.STL" />
      </geometry>
      <material
        name="">
        <color
          rgba="1 1 1 1" />
      </material>
    </visual>
    <collision>
      <origin
        xyz="0 0 0"
        rpy="0 0 0" />
      <geometry>
        <mesh
          filename="package://twoleg_foot_link/meshes/Right_Link6.STL" />
      </geometry>
    </collision>
  </link>
  <joint
    name="Right_Joint6"
    type="revolute">
    <origin
      xyz="0.0174 0 0.036"
      rpy="-1.7731 1.5708 1.4182" />
    <parent
      link="Right_Link5" />
    <child
      link="Right_Link6" />
    <axis
      xyz="0 0 -1" />
    <limit
      lower="-3.14"
      upper="3.14"
      effort="1"
      velocity="15" />
  </joint>
  <link
    name="Right_Foot">
    <inertial>
      <origin
        xyz="0 1.70093358977815E-19 0.0195816701322209"
        rpy="0 0 0" />
      <mass
        value="0.0394934474548918" />
      <inertia
        ixx="7.20293359743237E-06"
        ixy="-2.08687316618684E-23"
        ixz="8.47032947254299E-22"
        iyy="7.20293359743237E-06"
        iyz="-4.75596630259984E-22"
        izz="7.80281784174379E-06" />
    </inertial>
    <visual>
      <origin
        xyz="0 0 0"
        rpy="0 0 0" />
      <geometry>
        <mesh
          filename="package://twoleg_foot_link/meshes/Right_Foot.STL" />
      </geometry>
      <material
        name="">
        <color
          rgba="1 1 1 1" />
      </material>
    </visual>
    <collision>
      <origin
        xyz="0 0 0"
        rpy="0 0 0" />
      <geometry>
        <mesh
          filename="package://twoleg_foot_link/meshes/Right_Foot.STL" />
      </geometry>
    </collision>
  </link>
  <joint
    name="Right_Foot_Joint"
    type="fixed">
    <origin
      xyz="0 0 -0.011"
      rpy="3.1416 0 0" />
    <parent
      link="Right_Link6" />
    <child
      link="Right_Foot" />
    <axis
      xyz="0 0 0" />
  </joint>
</robot>